Workbook

Sheet Zoid
D2: =ifs(C7="Base",VLOOKUP(C4,Zoid_DB[],73,FALSE()),C7="Red",VLOOKUP(C4,Zoid_DB[],74,FALSE()),C7="Green",VLOOKUP(C4,Zoid_DB[],75,FALSE()),C7="Blue",VLOOKUP(C4,Zoid_DB[],76,FALSE()),C7="White",VLOOKUP(C4,Zoid_DB[],77,FALSE()),C7="Black",VLOOKUP(C4,Zoid_DB[],78,FALSE()),C7="Purple",VLOOKUP(C4,Zoid_DB[],79,FALSE()),C7="Brown",VLOOKUP(C4,Zoid_DB[],80,FALSE())) -> #NAME?
A3: Rest: | B3: Pilot Name: | C3: INSERT NAME | H3: =IF(C4="Gustav", "Gustav Trailer Type:", "") | I3: - - - - - -
A4: =FALSE() -> FALSE | B4: Zoid: | C4: Saberlion | H4: =IF(C4="Hover Cargo", "Cargo Unit Type:", "") | I4: - - - - - -
A5: Repair: | B5: Type: | C5: =VLOOKUP(C4,Zoid_DB[],3,FALSE()) -> Lion | H5: =IF(C4="Hover Cargo", "Cargo Unit Type:", "") | I5: - - - - - -
A6: =FALSE() -> FALSE | B6: Size: | C6: =VLOOKUP(C4,Zoid_DB[],4,FALSE()) -> Small | H6: =IF(C4="Whale King", "Cargo Unit Type:", "") | I6: - - - - - -
B7: Color: | C7: Base | H7: =IF(C4="Whale King", "Cargo Unit Type:", "") | I7: - - - - - -
B8: Level Required: | C8: =VLOOKUP(C4,Zoid_DB[],5,FALSE()) -> 3 | H8: =IF(C4="Whale King", "Cargo Unit Type:", "") | I8: - - - - - -
B9: Pilot Level: | C9: 1 | H9: =IF(C4="Whale King", "Cargo Unit Type:", "") | I9: - - - - - -
B10: Bonus Levels: | C10: =ifs( ISNUMBER(SEARCH(C5, Pilot!B14)), VLOOKUP(Pilot!B14,Skills[],3,FALSE()), ISNUMBER(SEARCH(C5, Pilot!B18)), VLOOKUP(Pilot!B18,Skills[],3,FALSE()), ISNUMBER(SEARCH(C5, Pilot!B22)), VLOOKUP(Pilot!B22,Skills[],3,FALSE()), ISNUMBER(SEARCH(C5, Pilot!B26)), VLOOKUP(Pilot!B26,Skills[],3,FALSE()), ISNUMBER(SEARCH(C5, Pilot!B30)), VLOOKUP(Pilot!B30,Skills[],3,FALSE()), ISNUMBER(SEARCH(C5, Pilot!B34)), VLOOKUP(Pilot!B34,Skills[],3,FALSE()), TRUE(), 0 ) -> #NAME?
B11: Pilot Style: | C11: FIGHTER
B12: STATS | C12: BASE | D12: WITH PILOT TOTAL | E12: CURRENT | F12: SHIELDS | G12: Damage to Shields
D13: =IFERROR(__xludf.dummyfunction("IFERROR(SPARKLINE(E14, {""charttype"", ""bar""; ""max"", D14; ""color1"", IF(E14 < D14*0.25, ""red"", IF(E14 < D14*0.5, ""yellow"", ""green""))}), """")"),"") | F13: =IFERROR(__xludf.dummyfunction("IFERROR(SPARKLINE(F14-G14, {""charttype"", ""bar""; ""max"", F14; ""color1"", IF(F14-G14=0, ""white"", IF((F14-G14) < F14*0.25, ""red"", IF((F14-G14) < F14*0.5, ""yellow"", ""blue""))) }), """")"),"")
B14: Health: | C14: =VLOOKUP(C4,Zoid_DB[],6,FALSE()) -> 90 | D14: =ROUND(C14+(C14* 'Dashboard (DO NOT TOUCH)'!C3),0) -> 144 | E14: 144 | F14: =ROUND( IF(OR(ISNUMBER(SEARCH("Passive", D50)), A47=TRUE()), VLOOKUP(C47,Armaments[],14,FALSE()), 0) + IF(OR(ISNUMBER(SEARCH("Passive", D57)), A54=TRUE()), VLOOKUP(C54,Armaments[],14,FALSE()), 0) + IF(OR(ISNUMBER(SEARCH("Passive", D64)), A61=TRUE()), VLOOKUP(C61,Armaments[],14,FALSE()), 0) + IF(OR(ISNUMBER(SEARCH("Passive", D71)), A68=TRUE()), VLOOKUP(C68,Armaments[],14,FALSE()), 0) + IF(A25=TRUE(), VLOOKUP(C4,Zoid_DB[],24,FALSE()), 0) + IF(A30=TRUE(), VLOOKUP(C4,Zoid_DB[],35,FALSE()), 0) + IF(A35=TRUE(), VLOOKUP(B78,Skills[],12,FALSE()), 0) + IF(A40=TRUE(), 'Dashboard (DO NOT TOUCH)'!G23, 0) + IF(G17=TRUE(), 'Dashboard (DO NOT TOUCH)'!G25, 0) - H14 ,0) -> 0 | G14: 0
B15: Armor (to get Hit): | C15: =VLOOKUP(C4,Zoid_DB[],7,FALSE()) -> 18 | D15: =ROUND(C15* 'Dashboard (DO NOT TOUCH)'!C4 +C15,0) -> 21 | E15: =ROUND(ifs( OR( ISNUMBER(SEARCH("Passive", C51)), A47=TRUE(), ISNUMBER(SEARCH("Passive", C58)), A54=TRUE(), ISNUMBER(SEARCH("Passive", C65)), A61=TRUE(), ISNUMBER(SEARCH("Passive", C73)), A68=TRUE() ), D15+VLOOKUP(C47,Armaments[],7,FALSE())+VLOOKUP(C54,Armaments[],7,FALSE())+VLOOKUP(C61,Armaments[],7,FALSE())+VLOOKUP(C68,Armaments[],7,FALSE()), TRUE(), D15) ,0) -> #NAME? | F15: Defense Up | G15: Defense Down
B16: Defense (damage blocked): | C16: =VLOOKUP(C4,Zoid_DB[],8,FALSE())+('Zoid Upgrades'!D5) -> #NAME? | D16: =C16 -> #NAME? | E16: =ROUND( IF( OR( ISNUMBER(SEARCH("Passive", C51)), A47=TRUE(), ISNUMBER(SEARCH("Passive", C58)), A54=TRUE(), ISNUMBER(SEARCH("Passive", C65)), A61=TRUE(), ISNUMBER(SEARCH("Passive", C72)), A68=TRUE() ), D16+VLOOKUP(C47,Armaments[],6,FALSE())+VLOOKUP(C54,Armaments[],6,FALSE())+VLOOKUP(C61,Armaments[],6,FALSE())+VLOOKUP(C68,Armaments[],6,FALSE())+VLOOKUP(B78,Skills[],13,FALSE())+VLOOKUP(B80,Skills[],13,FALSE())+VLOOKUP(B82,Skills[],13,FALSE())+VLOOKUP(B84,Skills[],13,FALSE())+VLOOKUP(B86,Skills[],13,FALSE())+VLOOKUP(B88,Skills[],13,FALSE())+ F16-G16, D16+F16-G16 ) + VLOOKUP(Pilot!B14,Skills[],15,FALSE()) + VLOOKUP(Pilot!B18,Skills[],15,FALSE()) + VLOOKUP(Pilot!B22,Skills[],15,FALSE()) + VLOOKUP(Pilot!B26,Skills[],15,FALSE()) + VLOOKUP(Pilot!B30,Skills[],15,FALSE()) + VLOOKUP(Pilot!B34,Skills[],15,FALSE()), 0) -> #NAME?
B17: Speed: | C17: =ROUNDUP(ifs(C21>C20,VLOOKUP(C4,Zoid_DB[],9,FALSE())*0.6,C10+C9<C8,VLOOKUP(C4,Zoid_DB[],9,FALSE())*0.6,C10+C9>=C8,VLOOKUP(C4,Zoid_DB[],9,FALSE())),0)+('Zoid Upgrades'!D3) -> #NAME? | D17: =ROUND(C17+('Dashboard (DO NOT TOUCH)'!D23*C17),0) -> #NAME? | E17: =D17+'Dashboard (DO NOT TOUCH)'!H11 -> #NAME? | F17: Organoid: | G17: =FALSE() -> FALSE
B18: Reaction: | C18: =ROUNDUP(ifs(C21>C20, VLOOKUP(C4,Zoid_DB[],10,FALSE())*0.6,C9+C10<C8,VLOOKUP(C4,Zoid_DB[],10,FALSE())*0.6,C9+C10>=C8,VLOOKUP(C4,Zoid_DB[],10,FALSE())),0)+('Zoid Upgrades'!D4) -> #NAME? | D18: =ROUND(C18* 'Dashboard (DO NOT TOUCH)'!C5 +C18,0) +Pilot!C5 -> #NAME? | E18: =ROUND(ifs( OR( ISNUMBER(SEARCH("Passive", C51)), A47=TRUE(), ISNUMBER(SEARCH("Passive", C58)), A54=TRUE(), ISNUMBER(SEARCH("Passive", C65)), A61=TRUE(), ISNUMBER(SEARCH("Passive", c72.)), A68=TRUE(), A25=TRUE(), A30=TRUE(), A35=TRUE(), A40=TRUE() ), D18+VLOOKUP(C47,Armaments[],10,FALSE())+VLOOKUP(C54,Armaments[],10,FALSE())+VLOOKUP(C61,Armaments[],10,FALSE())+VLOOKUP(C68,Armaments[],10,FALSE())+VLOOKUP(C4,Zoid_DB[],27,FALSE())+VLOOKUP(C4,Zoid_DB[],38,FALSE()), TRUE(), D18+VLOOKUP(B78,Skills[],10,FALSE())+VLOOKUP(B80,Skills[],10,FALSE())+VLOOKUP(B82,Skills[],10,FALSE())+VLOOKUP(B84,Skills[],10,FALSE())+VLOOKUP(B86,Skills[],10,FALSE())+VLOOKUP(B88,Skills[],10,FALSE())) ,0) -> #NAME? | F18: Level: | G18: 1
B19: Range: | C19: =VLOOKUP(C4,Zoid_DB[],11,FALSE()) -> 500 | D19: =C19* 'Dashboard (DO NOT TOUCH)'!C6 +C19 -> 625 | E19: =(D19+'Dashboard (DO NOT TOUCH)'!H12) -> 625 | F19: Color: | G19: Black
B20: Carry Capacity | C20: =VLOOKUP(C4,Zoid_DB[],12,FALSE())+('Zoid Upgrades'!D6) -> #NAME? | E20: Standard Weapon Range:
B21: Current Carry Load | C21: =SUM(VLOOKUP(C47,Armaments[],12,FALSE()),VLOOKUP(C61,Armaments[],12,FALSE()), VLOOKUP(C54,Armaments[],12,FALSE()), VLOOKUP(C68,Armaments[],12,FALSE())) -> 0 | E21: =D19/2 -> 312.5
B23: ACTIONS
C24: FIXED WEAPONS
A25: =FALSE() -> FALSE | B25: Weapon 1 | C25: =VLOOKUP(C4,Zoid_DB[],13,FALSE()) -> High Frequency Wave Claw: | D25: ="To Hit: " & ROUNDUP(ifs(C21>C20, VLOOKUP(C4,Zoid_DB[],17,FALSE())*0.6,C20>=C21,VLOOKUP(C4,Zoid_DB[],17,FALSE())),0)+('Zoid Upgrades'!D13) -> #NAME? | E25: ="To Hit With Pilot: " & ROUND(ROUNDUP(ifs(C21>C20, VLOOKUP(C4,Zoid_DB[],17,FALSE())*0.6,C20>=C21,VLOOKUP(C4,Zoid_DB[],17,FALSE())),0)*(1+'Dashboard (DO NOT TOUCH)'!B$7) + 'Dashboard (DO NOT TOUCH)'!H$13+ 'Dashboard (DO NOT TOUCH)'!H$14,0) -> #NAME?
C26: ="Damage Type: " & VLOOKUP(C4,Zoid_DB[],16,FALSE()) -> Damage Type: Melee, Slashing | D26: Upgrades to Damage: | F26: ="Attack Roll: " & IF($A$25=TRUE(), RANDBETWEEN(1,20),0) & "(+" & ROUND(ROUNDUP(ifs(C21>C20, VLOOKUP(C4,Zoid_DB[],17,FALSE())*0.6,C20>=C21,VLOOKUP(C4,Zoid_DB[],17,FALSE())),0)*(1+'Dashboard (DO NOT TOUCH)'!B$7) + 'Dashboard (DO NOT TOUCH)'!H$13+ 'Dashboard (DO NOT TOUCH)'!H$14,0)& ")" -> #NAME?
C27: ="Damage: " & VLOOKUP(C4,Zoid_DB[],15,FALSE()) & " +("& ROUND($D$27+((VLOOKUP(C4,Zoid_DB[],15,FALSE()) + $D$27)*'Dashboard (DO NOT TOUCH)'!H$23),0) &")" -> Damage: 35 +(20) | D27: ='Zoid Upgrades'!D12 -> 20
C28: ="Effect: " & VLOOKUP(C4,Zoid_DB[],14,FALSE()) -> Effect: Claw attack. Targets a single opponent. | D28: To Hit Increase: | E28: Speed Increase: | F28: ="Heat: " &VLOOKUP(C4,Zoid_DB[],85,FALSE()) -> Heat: | G28: Vent
C29: ="On/Off: "&VLOOKUP(C4,Zoid_DB[],18,FALSE()) -> On/Off: | D29: Reaction Increase: | E29: Range Increase: | F29: 0 | G29: =FALSE() -> FALSE
A30: =FALSE() -> FALSE | B30: Weapon 2 | C30: =VLOOKUP(C4,Zoid_DB[],19,FALSE()) -> High Frequency Wave Blade: | D30: ="To Hit: " & ROUNDUP(ifs(C21>C20, VLOOKUP(C4,Zoid_DB[],23,FALSE())*0.6,C20>=C21,VLOOKUP(C4,Zoid_DB[],23,FALSE())),0)+('Zoid Upgrades'!D16) -> #NAME? | E30: ="To Hit With Pilot: " & ROUND(ROUNDUP(ifs(C21>C20, VLOOKUP(C4,Zoid_DB[],23,FALSE())*0.6,C20>=C21,VLOOKUP(C4,Zoid_DB[],23,FALSE())),0)*(1+ 'Dashboard (DO NOT TOUCH)'!B$7) + 'Dashboard (DO NOT TOUCH)'!H$13+ 'Dashboard (DO NOT TOUCH)'!H$15,0) -> #NAME?
C31: ="Damage Type: " & VLOOKUP(C4,Zoid_DB[],22,FALSE()) -> Damage Type: Melee, Slashing | D31: Upgrades to Damage: | F31: ="Attack Roll: " & IF($A$30=TRUE(), RANDBETWEEN(1,20),0) & "(+" & ROUND(ROUNDUP(ifs(C21>C20, VLOOKUP(C4,Zoid_DB[],23,FALSE())*0.6,C20>=C21,VLOOKUP(C4,Zoid_DB[],23,FALSE())),0)*(1+ 'Dashboard (DO NOT TOUCH)'!B$7) + 'Dashboard (DO NOT TOUCH)'!H$13+ 'Dashboard (DO NOT TOUCH)'!H$15,0) & ")" -> #NAME?
C32: ="Damage: " & VLOOKUP(C4,Zoid_DB[],21,0) & " +("& ROUND($D$32+((VLOOKUP(C4,Zoid_DB[],21,FALSE()) + $D$32)*'Dashboard (DO NOT TOUCH)'!H$23),0) &")" -> #NAME? | D32: =('Zoid Upgrades'!D15) -> #NAME?
C33: ="Effect: " & VLOOKUP(C4,Zoid_DB[],20,FALSE()) -> Effect: Blade on top of head flips down. Targets a single opponent. | D33: ="To Hit Increase: "&VLOOKUP(C4,Zoid_DB[],26,FALSE()) -> To Hit Increase: | E33: ="Speed Increase: " &VLOOKUP(C4,Zoid_DB[],25,FALSE()) -> Speed Increase: | F33: ="Heat: " &VLOOKUP(C4,Zoid_DB[],86,FALSE()) -> Heat: | G33: Vent
C34: ="On/Off: "&VLOOKUP(C4,Zoid_DB[],29,FALSE()) -> On/Off: | D34: ="Reaction Increase: " & VLOOKUP(C4,Zoid_DB[],27,FALSE()) -> Reaction Increase: | E34: ="Range Increase: " &VLOOKUP(C4,Zoid_DB[],28,FALSE()) -> Range Increase: | F34: 0 | G34: =FALSE() -> FALSE
A35: =FALSE() -> FALSE | B35: Weapon 3 | C35: =VLOOKUP(C4,Zoid_DB[],30,FALSE()) -> Smoke Unit: | D35: =" To Hit: " & ROUNDUP(ifs(C21>C20, VLOOKUP(C4,Zoid_DB[],34,FALSE())*0.6,C20>=C21,VLOOKUP(C4,Zoid_DB[],34,FALSE())),0)+('Zoid Upgrades'!D19) -> #NAME? | E35: ="To Hit With Pilot: " & ROUND(ROUNDUP(ifs(C21>C20, VLOOKUP(C4,Zoid_DB[],34,FALSE())*0.6,C20>=C21,VLOOKUP(C4,Zoid_DB[],34,FALSE())),0)*(1+ 'Dashboard (DO NOT TOUCH)'!B$7) + 'Dashboard (DO NOT TOUCH)'!H$13+ 'Dashboard (DO NOT TOUCH)'!H$16,0) -> #NAME?
C36: ="Damage Type: " & VLOOKUP(C4,Zoid_DB[],33,FALSE()) -> Damage Type: | D36: Upgrades to Damage: | F36: ="Attack Roll: " & IF($A$35=TRUE(), RANDBETWEEN(1,20),0) & "(+" & ROUND(ROUNDUP(ifs(C21>C20, VLOOKUP(C4,Zoid_DB[],34,FALSE())*0.6,C20>=C21,VLOOKUP(C4,Zoid_DB[],34,FALSE())),0)*(1+ 'Dashboard (DO NOT TOUCH)'!B$7) + 'Dashboard (DO NOT TOUCH)'!H$13+ 'Dashboard (DO NOT TOUCH)'!H$16,0) & ")" -> #NAME?
C37: ="Damage: " & VLOOKUP(C4,Zoid_DB[],32,FALSE()) & " +("& ROUND($D$37+((VLOOKUP(C4,Zoid_DB[],32,FALSE()) + $D$37)*'Dashboard (DO NOT TOUCH)'!H$23),0) &")" -> #NAME? | D37: =('Zoid Upgrades'!D18) -> #NAME?
C38: ="Effect: "& VLOOKUP(C4,Zoid_DB[],31,FALSE()) -> Effect: Deploys smoke in a 30m square. While in the smoke attacks have disadvantage against you. Lasts three turns. | D38: ="To Hit Increase: "&VLOOKUP(C4,Zoid_DB[],37,FALSE()) -> To Hit Increase: | E38: ="Speed Increase: " &VLOOKUP(C4,Zoid_DB[],36,FALSE()) -> Speed Increase: | F38: ="Heat: " &VLOOKUP(C4,Zoid_DB[],87,FALSE()) -> Heat: | G38: Vent
C39: ="On/Off: "&VLOOKUP(C4,Zoid_DB[],40,FALSE()) -> On/Off: Active | D39: ="Reaction Increase: " & VLOOKUP(C4,Zoid_DB[],38,FALSE()) -> Reaction Increase: | E39: ="Range Increase: " &VLOOKUP(C4,Zoid_DB[],39,FALSE()) -> Range Increase: | F39: 0 | G39: =FALSE() -> FALSE
A40: =FALSE() -> FALSE | B40: Weapon 4 | C40: =VLOOKUP(C4,Zoid_DB[],41,FALSE()) -> High Frequency Wave Fang: | D40: =" To Hit: " & ROUNDUP(ifs(C21>C20, VLOOKUP(C4,Zoid_DB[],45,FALSE())*0.6,C20>=C21,VLOOKUP(C4,Zoid_DB[],45,FALSE())),0)+('Zoid Upgrades'!D22) -> #NAME? | E40: ="To Hit With Pilot: " & ROUND(ROUNDUP(ifs(C21>C20, VLOOKUP(C4,Zoid_DB[],45,FALSE())*0.6,C20>=C21,VLOOKUP(C4,Zoid_DB[],45,FALSE())),0)*(1+ 'Dashboard (DO NOT TOUCH)'!B$7) + 'Dashboard (DO NOT TOUCH)'!H$13+ 'Dashboard (DO NOT TOUCH)'!H$17,0) -> #NAME?
C41: ="Damage Type: " & VLOOKUP(C4,Zoid_DB[],44,FALSE()) -> Damage Type: Melee, Piercing | D41: Upgrades to Damage: | F41: ="Attack Roll: " & IF($A$40=TRUE(), RANDBETWEEN(1,20),0) & "(+" & ROUND(ROUNDUP(ifs(C21>C20, VLOOKUP(C4,Zoid_DB[],45,FALSE())*0.6,C20>=C21,VLOOKUP(C4,Zoid_DB[],45,FALSE())),0)*(1+ 'Dashboard (DO NOT TOUCH)'!B$7) + 'Dashboard (DO NOT TOUCH)'!H$13+ 'Dashboard (DO NOT TOUCH)'!H$17,0) & ")" -> #NAME?
C42: ="Damage: " & VLOOKUP(C4,Zoid_DB[],43,FALSE()) & " +("& ROUND($D$42+((VLOOKUP(C4,Zoid_DB[],43,FALSE()) + $D$42)*'Dashboard (DO NOT TOUCH)'!H$23),0) &")" -> #NAME? | D42: =('Zoid Upgrades'!D21) -> #NAME?
...

Sheet Pilot
B3: Name: | C3: =Zoid!C3 -> INSERT NAME | D3: Level: | E3: =Zoid!C9 -> 1 | G3: Inventory | H3: Gold:
B4: Physical: | C4: 2
B5: Mental: | C5: 3
B6: Social: | C6: 1
B7: Personality: | C7: =Zoid!G19 -> Black
B8: Zoid Pilot Style: | C8: =Zoid!C11 -> FIGHTER
B9: Current Zoid: | C9: =Zoid!C4 -> Saberlion
B13: ZOID ABILITIES | G13: INACTIVE ABILITIES | J13: Zi Database
B14: Lion Type 1 | D14: =VLOOKUP(B14,Skills[],2,FALSE()) -> Increases the pilots level by 5 while piloting the corresponding Zoid type.
D15: ="Levels: " & VLOOKUP(B14,Skills[],3,FALSE()) -> Levels: 5
D16: ="Zoid Stat Bonus: " -> Zoid Stat Bonus:
B18: - - - - - - - - - - | D18: =VLOOKUP(B18,Skills[],2,FALSE()) -> - - - - - - - - - - -
D19: ="Levels: " & VLOOKUP(B18,Skills[],3,FALSE()) -> Levels: 0
B22: - - - - - - - - - - | D22: =VLOOKUP(B22,Skills[],2,FALSE()) -> - - - - - - - - - - -
D23: ="Levels: " & VLOOKUP(B22,Skills[],3,FALSE()) -> Levels: 0
B26: - - - - - - - - - - | D26: =VLOOKUP(B26,Skills[],2,FALSE()) -> - - - - - - - - - - -
D27: ="Levels: " & VLOOKUP(B26,Skills[],3,FALSE()) -> Levels: 0
B30: - - - - - - - - - - | D30: =VLOOKUP(B30,Skills[],2,FALSE()) -> - - - - - - - - - - -
D31: ="Levels: " & VLOOKUP(B30,Skills[],3,FALSE()) -> Levels: 0
B34: - - - - - - - - - - | D34: =VLOOKUP(B34,Skills[],2,FALSE()) -> - - - - - - - - - - -
D35: ="Levels: " & VLOOKUP(B34,Skills[],3,FALSE()) -> Levels: 0
B40: Feats
B41: - - - - - - | C41: =VLOOKUP(B41, Feats[], 2, FALSE()) -> - - - - - -
B42: - - - - - - | C42: =VLOOKUP(B42, Feats[], 2, FALSE()) -> - - - - - -
B43: - - - - - - | C43: =VLOOKUP(B43, Feats[], 2, FALSE()) -> - - - - - -
B44: - - - - - - | C44: =VLOOKUP(B44, Feats[], 2, FALSE()) -> - - - - - -
B45: - - - - - - | C45: =VLOOKUP(B45, Feats[], 2, FALSE()) -> - - - - - -
B46: - - - - - - | C46: =VLOOKUP(B46, Feats[], 2, FALSE()) -> - - - - - -
B47: - - - - - - | C47: =VLOOKUP(B47, Feats[], 2, FALSE()) -> - - - - - -

Sheet Zoid Upgrades
D1: Zoid: | E1: Saberlion | F1: Berserk Fury | G1: Liger Zero | H1: Zoid 4 | I1: Zoid 5 | J1: Zoid 6 | K1: Zoid 7 | L1: Zoid 8
A2: Zoid Upgrades | B2: 5000x | C2: Points (X/5) | D2: Total Bonus
A3: Speed | B3: +30/point | D3: =ifs(Zoid!C4 = E1, E3, Zoid!C4 = F1, F3, Zoid!C4 = G1, G3, Zoid!C4 = H1, H3, Zoid!C4 = I1, I3, Zoid!C4 = J1, J3, Zoid!C4 = K1, K3, Zoid!C4 = L1, L3) -> #NAME?
A4: Reaction | B4: +1/point | D4: =ifs(Zoid!C4 = E1, E4, Zoid!C4 = F1, F4, Zoid!C4 = G1, G4, Zoid!C4 = H1, H4, Zoid!C4 = I1, I4, Zoid!C4 = J1, J4, Zoid!C4 = K1, K4, Zoid!C4 = L1, L4) -> #NAME?
A5: Defense | B5: +5/point | D5: =ifs(Zoid!C4 = E1, E5, Zoid!C4 = F1, F5, Zoid!C4 = G1, G5, Zoid!C4 = H1, H5, Zoid!C4 = I1, I5, Zoid!C4 = J1, J5, Zoid!C4 = K1, K5, Zoid!C4 = L1, L5) -> #NAME?
A6: Weapon Weight | B6: +10/point | D6: =ifs(Zoid!C4 = E1, E6, Zoid!C4 = F1, F6, Zoid!C4 = G1, G6, Zoid!C4 = H1, H6, Zoid!C4 = I1, I6, Zoid!C4 = J1, J6, Zoid!C4 = K1, K6, Zoid!C4 = L1, L6) -> #NAME?
A8: Max 5 points in each slot
A10: Fixed Weapons | B10: 10,000x | C10: Point (X/5) | D10: Total Bonus | E10: Weapon Name | F10: Only Weapons can be upgrade, not other units like an Energy Shield or Smoke Unit
E11: =VLOOKUP(E1,Zoid_DB[],13,FALSE()) -> High Frequency Wave Claw: | F11: =VLOOKUP(F1,Zoid_DB[],13,FALSE()) -> Buster Claw: | G11: =VLOOKUP(G1,Zoid_DB[],13,FALSE()) -> Shock Cannon: | H11: =VLOOKUP(H1,Zoid_DB[],13,FALSE()) -> #N/A | I11: =VLOOKUP(I1,Zoid_DB[],13,FALSE()) -> #N/A | J11: =VLOOKUP(J1,Zoid_DB[],13,FALSE()) -> #N/A | K11: =VLOOKUP(K1,Zoid_DB[],13,FALSE()) -> #N/A | L11: =VLOOKUP(L1,Zoid_DB[],13,FALSE()) -> #N/A
A12: F1 Damage | B12: +20/point | D12: =ifs(Zoid!C4 = E1, E12, Zoid!C4 = F1, F12, Zoid!C4 = G1, G12, Zoid!C4 = H1, H12, Zoid!C4 = I1, I12, Zoid!C4 = J1, J12, Zoid!C4 = K1, K12, Zoid!C4 = L1, L12) -> 20 | E12: 20
A13: F1 To Hit | B13: +1/point | D13: =ifs(Zoid!C4 = E1, E13, Zoid!C4 = F1, F13, Zoid!C4 = G1, G13, Zoid!C4 = H1, H13, Zoid!C4 = I1, I13, Zoid!C4 = J1, J13, Zoid!C4 = K1, K13, Zoid!C4 = L1, L13) -> #NAME?
E14: =VLOOKUP(E1,Zoid_DB[],19,FALSE()) -> High Frequency Wave Blade: | F14: =VLOOKUP(F1,Zoid_DB[],19,FALSE()) -> Diffuse Particle Cannon: | G14: =VLOOKUP(G1,Zoid_DB[],19,FALSE()) -> Ion Boosters: | H14: =VLOOKUP(H1,Zoid_DB[],19,FALSE()) -> #N/A | I14: =VLOOKUP(I1,Zoid_DB[],19,FALSE()) -> #N/A | J14: =VLOOKUP(J1,Zoid_DB[],19,FALSE()) -> #N/A | K14: =VLOOKUP(K1,Zoid_DB[],19,FALSE()) -> #N/A | L14: =VLOOKUP(L1,Zoid_DB[],19,FALSE()) -> #N/A
A15: F2 Damage | B15: +20/point | D15: =ifs(Zoid!C4 = E1, E15, Zoid!C4 = F1, F15, Zoid!C4 = G1, G15, Zoid!C4 = H1, H15, Zoid!C4 = I1, I15, Zoid!C4 = J1, J15, Zoid!C4 = K1, K15, Zoid!C4 = L1, L15) -> #NAME?
A16: F2 To Hit | B16: +1/point | D16: =ifs(Zoid!C4 = E1, E16, Zoid!C4 = F1, F16, Zoid!C4 = G1, G16, Zoid!C4 = H1, H16, Zoid!C4 = I1, I16, Zoid!C4 = J1, J16, Zoid!C4 = K1, K16, Zoid!C4 = L1, L16) -> #NAME?
E17: =VLOOKUP(E1,Zoid_DB[],30,FALSE()) -> Smoke Unit: | F17: =VLOOKUP(F1,Zoid_DB[],30,FALSE()) -> Energy Shield: | G17: =VLOOKUP(G1,Zoid_DB[],30,FALSE()) -> Strike Laster Claw: | H17: =VLOOKUP(H1,Zoid_DB[],30,FALSE()) -> #N/A | I17: =VLOOKUP(I1,Zoid_DB[],30,FALSE()) -> #N/A | J17: =VLOOKUP(J1,Zoid_DB[],30,FALSE()) -> #N/A | K17: =VLOOKUP(K1,Zoid_DB[],30,FALSE()) -> #N/A | L17: =VLOOKUP(L1,Zoid_DB[],30,FALSE()) -> #N/A
A18: F3 Damage | B18: +20/point | D18: =ifs(Zoid!C4 = E1, E18, Zoid!C4 = F1, F18, Zoid!C4 = G1, G18, Zoid!C4 = H1, H18, Zoid!C4 = I1, I18, Zoid!C4 = J1, J18, Zoid!C4 = K1, K18, Zoid!C4 = L1, L18) -> #NAME?
A19: F3 To Hit | B19: +1/point | D19: =ifs(Zoid!C4 = E1, E19, Zoid!C4 = F1, F19, Zoid!C4 = G1, G19, Zoid!C4 = H1, H19, Zoid!C4 = I1, I19, Zoid!C4 = J1, J19, Zoid!C4 = K1, K19, Zoid!C4 = L1, L19) -> #NAME?
E20: =VLOOKUP(E1,Zoid_DB[],41,FALSE()) -> High Frequency Wave Fang: | F20: =VLOOKUP(F1,Zoid_DB[],41,FALSE()) -> Strike Laser Claw: | G20: =VLOOKUP(G1,Zoid_DB[],41,FALSE()) -> 0 | H20: =VLOOKUP(H1,Zoid_DB[],41,FALSE()) -> #N/A | I20: =VLOOKUP(I1,Zoid_DB[],41,FALSE()) -> #N/A | J20: =VLOOKUP(J1,Zoid_DB[],41,FALSE()) -> #N/A | K20: =VLOOKUP(K1,Zoid_DB[],41,FALSE()) -> #N/A | L20: =VLOOKUP(L1,Zoid_DB[],41,FALSE()) -> #N/A
A21: F4 Damage | B21: +20/point | D21: =ifs(Zoid!C4 = E1, E21, Zoid!C4 = F1, F21, Zoid!C4 = G1, G21, Zoid!C4 = H1, H21, Zoid!C4 = I1, I21, Zoid!C4 = J1, J21, Zoid!C4 = K1, K21, Zoid!C4 = L1, L21) -> #NAME?
A22: F4 To Hit | B22: +1/point | D22: =ifs(Zoid!C4 = E1, E22, Zoid!C4 = F1, F22, Zoid!C4 = G1, G22, Zoid!C4 = H1, H22, Zoid!C4 = I1, I22, Zoid!C4 = J1, J22, Zoid!C4 = K1, K22, Zoid!C4 = L1, L22) -> #NAME?
A24: Upgrades of the same weapon between CAS Units transfer. Frame upgrades also transfer between CAS units. Be sure to enter upgrades in each field they apply.
A26: This Sheet is set up to track 8 different Zoids (or CAS units)

Sheet Dashboard (DO NOT TOUCH)
A1: Fighting Style | B1: =Zoid!C11 -> FIGHTER | D1: Tank | E1: Fighter | F1: Scout | G1: Almighty
A2: Level | B2: =Zoid!C9+Zoid!C10 -> #NAME?
A3: Health | B3: =IF(B$1="TANK",D3,IF(B$1="FIGHTER",E3,IF(B$1="SCOUT",F3,IF(B$1="ALMIGHTY",G3,"Titties")))) -> #NAME? | C3: =IFERROR(__xludf.dummyfunction("TO_PERCENT( IFS( ISNUMBER(SEARCH(Zoid!C6, VLOOKUP(Pilot!B14, Skills, 4, FALSE))), 'Dashboard (DO NOT TOUCH)'!B3 + VLOOKUP(Pilot!B14, Skills, 5, FALSE), ISNUMBER(SEARCH(Zoid!C6, VLOOKUP(Pilot!B18, Skills, 4, FALSE))), 'Dashboard (DO NOT TOUCH)'"&"!B3 + VLOOKUP(Pilot!B18, Skills, 5, FALSE), ISNUMBER(SEARCH(Zoid!C6, VLOOKUP(Pilot!B22, Skills, 4, FALSE))), 'Dashboard (DO NOT TOUCH)'!B3 + VLOOKUP(Pilot!B22, Skills, 5, FALSE), ISNUMBER(SEARCH(Zoid!C6, VLOOKUP(Pilot!B26, Skills, 4, FALSE))), '"&"Dashboard (DO NOT TOUCH)'!B3 + VLOOKUP(Pilot!B26, Skills, 5, FALSE), ISNUMBER(SEARCH(Zoid!C6, VLOOKUP(Pilot!B30, Skills, 4, FALSE))), 'Dashboard (DO NOT TOUCH)'!B3 + VLOOKUP(Pilot!B30, Skills, 5, FALSE), ISNUMBER(SEARCH(Zoid!C6, VLOOKUP(Pilot!B3"&"4, Skills, 4, FALSE))), 'Dashboard (DO NOT TOUCH)'!B3 + VLOOKUP(Pilot!B34, Skills, 5, FALSE), TRUE, 'Dashboard (DO NOT TOUCH)'!B3 ) + B23 ) "),0.6) -> 0.6 | D3: {=INDEX(TANK[], MATCH('Dashboard (DO NOT TOUCH)'!B2, INDEX(TANK[],,1), 0), MATCH("Health", TANK[#Headers], 0))} -> #NAME? | E3: {=INDEX(FIGHTER[], MATCH('Dashboard (DO NOT TOUCH)'!B2, INDEX(FIGHTER[],,1), 0), MATCH("Health", FIGHTER[#Headers], 0))} -> #NAME? | F3: {=INDEX(SCOUT[], MATCH('Dashboard (DO NOT TOUCH)'!B2, INDEX(SCOUT[],,1), 0), MATCH("Health", SCOUT[#Headers], 0))} -> #NAME? | G3: {=INDEX(ALMIGHTY[], MATCH('Dashboard (DO NOT TOUCH)'!B2, INDEX(ALMIGHTY[],,1), 0), MATCH("Health", ALMIGHTY[#Headers], 0))} -> #NAME?
A4: Armor | B4: =IF(B$1="TANK",D4,IF(B$1="FIGHTER",E4,IF(B$1="SCOUT",F4,IF(B$1="ALMIGHTY",G4,"Titties")))) -> #NAME? | C4: =IFERROR(__xludf.dummyfunction("To_Percent(IFS( ISNUMBER(SEARCH(Zoid!C6, VLOOKUP(Pilot!B14, Skills, 4, FALSE))), 'Dashboard (DO NOT TOUCH)'!B4 + VLOOKUP(Pilot!B14, Skills, 5, FALSE) + VLOOKUP(Pilot!B14, Skills, 6, FALSE) + VLOOKUP(Pilot!B18, Skills, 6, FALSE) + VLOOKUP(Pilot!B22, S"&"kills, 6, FALSE) + VLOOKUP(Pilot!B26, Skills, 6, FALSE) + VLOOKUP(Pilot!B30, Skills, 6, FALSE) + VLOOKUP(Pilot!B34, Skills, 6, FALSE), ISNUMBER(SEARCH(Zoid!C6, VLOOKUP(Pilot!B18 , Skills, 4, FALSE))), 'Dashboard (DO NOT TOUCH)'!B4 + VLOOKUP(Pilot!B18,"&" Skills, 5, FALSE) + VLOOKUP(Pilot!B14, Skills, 6, FALSE) + VLOOKUP(Pilot!B18, Skills, 6, FALSE) + VLOOKUP(Pilot!B22, Skills, 6, FALSE) + VLOOKUP(Pilot!B26, Skills, 6, FALSE) + VLOOKUP(Pilot!B30, Skills, 6, FALSE) + VLOOKUP(Pilot!B34, Skills, 6, FALSE), "&" ISNUMBER(SEARCH(Zoid!C6, VLOOKUP(Pilot!B22, Skills, 4, FALSE))), 'Dashboard (DO NOT TOUCH)'!B4+ VLOOKUP(Pilot!B22, Skills, 5, FALSE) + VLOOKUP(Pilot!B14, Skills, 6, FALSE) + VLOOKUP(Pilot!B18, Skills, 6, FALSE) + VLOOKUP(Pilot!B22, Skills, 6, FALSE) "&"+ VLOOKUP(Pilot!B26, Skills, 6, FALSE) + VLOOKUP(Pilot!B30, Skills, 6, FALSE) + VLOOKUP(Pilot!B34, Skills, 6, FALSE), ISNUMBER(SEARCH(Zoid!C6, VLOOKUP(Pilot!B26, Skills, 4, FALSE))), 'Dashboard (DO NOT TOUCH)'!B4 + VLOOKUP(Pilot!B26, Skills, 5, FALSE)"&" + VLOOKUP(Pilot!B14, Skills, 6, FALSE) + VLOOKUP(Pilot!B18, Skills, 6, FALSE) + VLOOKUP(Pilot!B22, Skills, 6, FALSE) + VLOOKUP(Pilot!B26, Skills, 6, FALSE) + VLOOKUP(Pilot!B30, Skills, 6, FALSE) + VLOOKUP(Pilot!B34, Skills, 6, FALSE), ISNUMBER(SEARC"&"H(Zoid!C6, VLOOKUP(Pilot!B30, Skills, 4, FALSE))), 'Dashboard (DO NOT TOUCH)'!B4+ VLOOKUP(Pilot!B30, Skills, 5, FALSE) + VLOOKUP(Pilot!B14, Skills, 6, FALSE) + VLOOKUP(Pilot!B18, Skills, 6, FALSE) + VLOOKUP(Pilot!B22, Skills, 6, FALSE) + VLOOKUP(Pilot!B2"&"6, Skills, 6, FALSE) + VLOOKUP(Pilot!B30, Skills, 6, FALSE) + VLOOKUP(Pilot!B34, Skills, 6, FALSE), ISNUMBER(SEARCH(Zoid!C6, VLOOKUP(Pilot!B34, Skills, 4, FALSE))), 'Dashboard (DO NOT TOUCH)'!B4+ VLOOKUP(Pilot!B34, Skills, 5, FALSE) + VLOOKUP(Pilot!B1"&"4, Skills, 6, FALSE) + VLOOKUP(Pilot!B18, Skills, 6, FALSE) + VLOOKUP(Pilot!B22, Skills, 6, FALSE) + VLOOKUP(Pilot!B26, Skills, 6, FALSE) + VLOOKUP(Pilot!B30, Skills, 6, FALSE) + VLOOKUP(Pilot!B34, Skills, 6, FALSE), TRUE, 'Dashboard (DO NOT TOUCH)'!"&"B4 )+C23)"),0.15) -> 0.15 | D4: {=INDEX(TANK[], MATCH('Dashboard (DO NOT TOUCH)'!B2, INDEX(TANK[],,1), 0), MATCH("Armor", TANK[#Headers], 0))} -> #NAME? | E4: {=INDEX(FIGHTER[], MATCH('Dashboard (DO NOT TOUCH)'!B2, INDEX(FIGHTER[],,1), 0), MATCH("Armor", FIGHTER[#Headers], 0))} -> #NAME? | F4: {=INDEX(SCOUT[], MATCH('Dashboard (DO NOT TOUCH)'!B2, INDEX(SCOUT[],,1), 0), MATCH("Armor", SCOUT[#Headers], 0))} -> #NAME? | G4: {=INDEX(ALMIGHTY[], MATCH('Dashboard (DO NOT TOUCH)'!B2, INDEX(ALMIGHTY[],,1), 0), MATCH("Armor", ALMIGHTY[#Headers], 0))} -> #NAME?
A5: React | B5: =IF(B$1="TANK",D5,IF(B$1="FIGHTER",E5,IF(B$1="SCOUT",F5,IF(B$1="ALMIGHTY",G5,"Titties")))) -> #NAME? | C5: =IFERROR(__xludf.dummyfunction("To_Percent(IFS( ISNUMBER(SEARCH(Zoid!C6, VLOOKUP(Pilot!B14, Skills, 4, FALSE))), 'Dashboard (DO NOT TOUCH)'!B5 + VLOOKUP(Pilot!B14, Skills, 5, FALSE), ISNUMBER(SEARCH(Zoid!C6, VLOOKUP(Pilot!B18 , Skills, 4, FALSE))), 'Dashboard (DO NOT TOUCH)'!B5 "&"+ VLOOKUP(Pilot!B18, Skills, 5, FALSE), ISNUMBER(SEARCH(Zoid!C6, VLOOKUP(Pilot!B22, Skills, 4, FALSE))), 'Dashboard (DO NOT TOUCH)'!B5 + VLOOKUP(Pilot!B22, Skills, 5, FALSE), ISNUMBER(SEARCH(Zoid!C6, VLOOKUP(Pilot!B26, Skills, 4, FALSE))), 'Dashbo"&"ard (DO NOT TOUCH)'!B5 + VLOOKUP(Pilot!B26, Skills, 5, FALSE), ISNUMBER(SEARCH(Zoid!C6, VLOOKUP(Pilot!B30, Skills, 4, FALSE))), 'Dashboard (DO NOT TOUCH)'!B5 + VLOOKUP(Pilot!B30, Skills, 5, FALSE), ISNUMBER(SEARCH(Zoid!C6, VLOOKUP(Pilot!B34, Skill"&"s, 4, FALSE))), 'Dashboard (DO NOT TOUCH)'!B5 + VLOOKUP(Pilot!B34, Skills, 5, FALSE), TRUE, 'Dashboard (DO NOT TOUCH)'!B5 ))"),0.15) -> 0.15 | D5: {=INDEX(TANK[], MATCH('Dashboard (DO NOT TOUCH)'!B2, INDEX(TANK[],,1), 0), MATCH("React", TANK[#Headers], 0))} -> #NAME? | E5: {=INDEX(FIGHTER[], MATCH('Dashboard (DO NOT TOUCH)'!B2, INDEX(FIGHTER[],,1), 0), MATCH("React", FIGHTER[#Headers], 0))} -> #NAME? | F5: {=INDEX(SCOUT[], MATCH('Dashboard (DO NOT TOUCH)'!B2, INDEX(SCOUT[],,1), 0), MATCH("React", SCOUT[#Headers], 0))} -> #NAME? | G5: {=INDEX(ALMIGHTY[], MATCH('Dashboard (DO NOT TOUCH)'!B2, INDEX(ALMIGHTY[],,1), 0), MATCH("React", ALMIGHTY[#Headers], 0))} -> #NAME?
A6: Perception | B6: =IF(B$1="TANK",D6,IF(B$1="FIGHTER",E6,IF(B$1="SCOUT",F6,IF(B$1="ALMIGHTY",G6,"Titties")))) -> #NAME? | C6: =IFERROR(__xludf.dummyfunction("To_Percent(IFS( ISNUMBER(SEARCH(Zoid!C6, VLOOKUP(Pilot!B14, Skills, 4, FALSE))), 'Dashboard (DO NOT TOUCH)'!B6 + VLOOKUP(Pilot!B14, Skills, 5, FALSE), ISNUMBER(SEARCH(Zoid!C6, VLOOKUP(Pilot!B18 , Skills, 4, FALSE))), 'Dashboard (DO NOT TOUCH)'!B6 "&"+ VLOOKUP(Pilot!B18, Skills, 5, FALSE), ISNUMBER(SEARCH(Zoid!C6, VLOOKUP(Pilot!B22, Skills, 4, FALSE))), 'Dashboard (DO NOT TOUCH)'!B6 + VLOOKUP(Pilot!B22, Skills, 5, FALSE), ISNUMBER(SEARCH(Zoid!C6, VLOOKUP(Pilot!B26, Skills, 4, FALSE))), 'Dashbo"&"ard (DO NOT TOUCH)'!B6 + VLOOKUP(Pilot!B26, Skills, 5, FALSE), ISNUMBER(SEARCH(Zoid!C6, VLOOKUP(Pilot!B30, Skills, 4, FALSE))), 'Dashboard (DO NOT TOUCH)'!B6 + VLOOKUP(Pilot!B30, Skills, 5, FALSE), ISNUMBER(SEARCH(Zoid!C6, VLOOKUP(Pilot!B34, Skill"&"s, 4, FALSE))), 'Dashboard (DO NOT TOUCH)'!B6 + VLOOKUP(Pilot!B34, Skills, 5, FALSE), TRUE, 'Dashboard (DO NOT TOUCH)'!B6 )+E23)"),0.25) -> 0.25 | D6: {=INDEX(TANK[], MATCH('Dashboard (DO NOT TOUCH)'!B2, INDEX(TANK[],,1), 0), MATCH("Perception", TANK[#Headers], 0))} -> #NAME? | E6: {=INDEX(FIGHTER[], MATCH('Dashboard (DO NOT TOUCH)'!B2, INDEX(FIGHTER[],,1), 0), MATCH("Perception", FIGHTER[#Headers], 0))} -> #NAME? | F6: {=INDEX(SCOUT[], MATCH('Dashboard (DO NOT TOUCH)'!B2, INDEX(SCOUT[],,1), 0), MATCH("Perception", SCOUT[#Headers], 0))} -> #NAME? | G6: {=INDEX(ALMIGHTY[], MATCH('Dashboard (DO NOT TOUCH)'!B2, INDEX(ALMIGHTY[],,1), 0), MATCH("Perception", ALMIGHTY[#Headers], 0))} -> #NAME?
A7: To Hit | B7: =IF(B$1="TANK",D7,IF(B$1="FIGHTER",E7,IF(B$1="SCOUT",F7,IF(B$1="ALMIGHTY",G7,"Titties")))) -> #NAME? | C7: =IFERROR(__xludf.dummyfunction("To_Percent(IFS( ISNUMBER(SEARCH(Zoid!C6, VLOOKUP(Pilot!B14, Skills, 4, FALSE))), 'Dashboard (DO NOT TOUCH)'!B7 + VLOOKUP(Pilot!B14, Skills, 5, FALSE), ISNUMBER(SEARCH(Zoid!C6, VLOOKUP(Pilot!B18 , Skills, 4, FALSE))), 'Dashboard (DO NOT TOUCH)'!B7 "&"+ VLOOKUP(Pilot!B18, Skills, 5, FALSE), ISNUMBER(SEARCH(Zoid!C6, VLOOKUP(Pilot!B22, Skills, 4, FALSE))), 'Dashboard (DO NOT TOUCH)'!B7 + VLOOKUP(Pilot!B22, Skills, 5, FALSE), ISNUMBER(SEARCH(Zoid!C6, VLOOKUP(Pilot!B26, Skills, 4, FALSE))), 'Dashbo"&"ard (DO NOT TOUCH)'!B7+ VLOOKUP(Pilot!B26, Skills, 5, FALSE), ISNUMBER(SEARCH(Zoid!C6, VLOOKUP(Pilot!B30, Skills, 4, FALSE))), 'Dashboard (DO NOT TOUCH)'!B7 + VLOOKUP(Pilot!B30, Skills, 5, FALSE), ISNUMBER(SEARCH(Zoid!C6, VLOOKUP(Pilot!B34, Skills"&", 4, FALSE))), 'Dashboard (DO NOT TOUCH)'!B7 + VLOOKUP(Pilot!B34, Skills, 5, FALSE), TRUE, 'Dashboard (DO NOT TOUCH)'!B7 )+F23)"),0.25) -> 0.25 | D7: {=INDEX(TANK[], MATCH('Dashboard (DO NOT TOUCH)'!B2, INDEX(TANK[],,1), 0), MATCH("To Hit", TANK[#Headers], 0))} -> #NAME? | E7: {=INDEX(FIGHTER[], MATCH('Dashboard (DO NOT TOUCH)'!B2, INDEX(FIGHTER[],,1), 0), MATCH("To Hit", FIGHTER[#Headers], 0))} -> #NAME? | F7: {=INDEX(SCOUT[], MATCH('Dashboard (DO NOT TOUCH)'!B2, INDEX(SCOUT[],,1), 0), MATCH("To Hit", SCOUT[#Headers], 0))} -> #NAME? | G7: {=INDEX(ALMIGHTY[], MATCH('Dashboard (DO NOT TOUCH)'!B2, INDEX(ALMIGHTY[],,1), 0), MATCH("To Hit", ALMIGHTY[#Headers], 0))} -> #NAME?
H10: Total
A11: Speed: | B11: =IF(Zoid!A30=TRUE(),VLOOKUP(Zoid!C4,Zoid_DB[],25,FALSE()),0) -> 0 | C11: =IF(Zoid!A35=TRUE(),VLOOKUP(Zoid!C4,Zoid_DB[],36,FALSE()),0) -> 0 | D11: =IF(Zoid!A47=TRUE(),VLOOKUP(Zoid!C47,Armaments[],11,FALSE()),0) -> 0 | E11: =IF(Zoid!A54=TRUE(),VLOOKUP(Zoid!C54,Armaments[],11,FALSE()),0) -> 0 | F11: =IF(Zoid!A61=TRUE(),VLOOKUP(Zoid!C61,Armaments[],11,FALSE()),0) -> 0 | G11: =IF(Zoid!A68=TRUE(),VLOOKUP(Zoid!C68,Armaments[],11,FALSE()),0) -> 0 | H11: =SUM(B11:G11) -> 0
A12: Range: | B12: =IF(Zoid!A30=TRUE(),VLOOKUP(Zoid!C4,Zoid_DB[],28,FALSE()),0) -> 0 | C12: =IF(Zoid!A35=TRUE(),VLOOKUP(Zoid!C4,Zoid_DB[],39,FALSE()),0) -> 0 | D12: =IF(Zoid!A47=TRUE(),VLOOKUP(Zoid!C47,Armaments[],9,FALSE()),0) -> 0 | E12: =IF(Zoid!A54=TRUE(),VLOOKUP(Zoid!C54,Armaments[],9,FALSE()),0) -> 0 | F12: =IF(Zoid!A61=TRUE(),VLOOKUP(Zoid!C61,Armaments[],9,FALSE()),0) -> 0 | G12: =IF(Zoid!A68=TRUE(),VLOOKUP(Zoid!C68,Armaments[],9,FALSE()),0) -> 0 | H12: =SUM(B12, C12, D12, E12, F12, G12) -> 0
A13: To Hit: | B13: =IF(Zoid!A30=TRUE(),VLOOKUP(Zoid!C4,Zoid_DB[],26,FALSE()),0) -> 0 | C13: =IF(Zoid!A35=TRUE(),VLOOKUP(Zoid!C4,Zoid_DB[],37,FALSE()),0) -> 0 | D13: =IF(Zoid!A47=TRUE(),VLOOKUP(Zoid!C47,Armaments[],8,FALSE()),0) -> 0 | E13: =IF(Zoid!A54=TRUE(),VLOOKUP(Zoid!C54,Armaments[],8,FALSE()),0) -> 0 | F13: =IF(Zoid!A61=TRUE(),VLOOKUP(Zoid!C61,Armaments[],8,FALSE()),0) -> 0 | G13: =IF(Zoid!A68=TRUE(),VLOOKUP(Zoid!C68,Armaments[],8,FALSE()),0) -> 0 | H13: =SUM(B13, C13, D13, E13, F13, G13) -> 0 | I13: From equipment
B14: =IF(ISNUMBER(SEARCH(IFERROR(VLOOKUP(Pilot!B14,Skills[],14,0),"#"), Zoid!C26)), IFERROR(VLOOKUP(Pilot!B14,Skills[],7,0), 0), 0) -> 0 | C14: =IF(ISNUMBER(SEARCH(IFERROR(VLOOKUP(Pilot!B18,Skills[],14,0),"#"), Zoid!C26)), IFERROR(VLOOKUP(Pilot!B18,Skills[],7,0), 0), 0) -> 0 | D14: =IF(ISNUMBER(SEARCH(IFERROR(VLOOKUP(Pilot!B22,Skills[],14,0),"#"), Zoid!C26)), IFERROR(VLOOKUP(Pilot!B22,Skills[],7,0), 0), 0) -> 0 | E14: =IF(ISNUMBER(SEARCH(IFERROR(VLOOKUP(Pilot!B26,Skills[],14,0),"#"), Zoid!C26)), IFERROR(VLOOKUP(Pilot!B26,Skills[],7,0), 0), 0) -> 0 | F14: =IF(ISNUMBER(SEARCH(IFERROR(VLOOKUP(Pilot!B30,Skills[],14,0),"#"), Zoid!C26)), IFERROR(VLOOKUP(Pilot!B30,Skills[],7,0), 0), 0) -> 0 | G14: =IF(ISNUMBER(SEARCH(IFERROR(VLOOKUP(Pilot!B34,Skills[],14,0),"#"), Zoid!C26)), IFERROR(VLOOKUP(Pilot!B34,Skills[],7,0), 0), 0) -> 0 | H14: =SUM(B14, C14, D14, E14, F14, G14) -> 0 | I14: Weapon 1
B15: =IF(ISNUMBER(SEARCH(IFERROR(VLOOKUP(Pilot!B15,Skills[],14,0),"#"), Zoid!C31)), IFERROR(VLOOKUP(Pilot!B15,Skills[],7,0), 0), 0) -> 0 | C15: =IF(ISNUMBER(SEARCH(IFERROR(VLOOKUP(Pilot!B19,Skills[],14,0),"#"), Zoid!C31)), IFERROR(VLOOKUP(Pilot!B19,Skills[],7,0), 0), 0) -> 0 | D15: =IF(ISNUMBER(SEARCH(IFERROR(VLOOKUP(Pilot!B23,Skills[],14,0),"#"), Zoid!C31)), IFERROR(VLOOKUP(Pilot!B23,Skills[],7,0), 0), 0) -> 0 | E15: =IF(ISNUMBER(SEARCH(IFERROR(VLOOKUP(Pilot!B27,Skills[],14,0),"#"), Zoid!C31)), IFERROR(VLOOKUP(Pilot!B27,Skills[],7,0), 0), 0) -> 0 | F15: =IF(ISNUMBER(SEARCH(IFERROR(VLOOKUP(Pilot!B31,Skills[],14,0),"#"), Zoid!C31)), IFERROR(VLOOKUP(Pilot!B31,Skills[],7,0), 0), 0) -> 0 | G15: =IF(ISNUMBER(SEARCH(IFERROR(VLOOKUP(Pilot!B35,Skills[],14,0),"#"), Zoid!C31)), IFERROR(VLOOKUP(Pilot!B35,Skills[],7,0), 0), 0) -> 0 | H15: =SUM(B15, C15, D15, E15, F15, G15) -> 0 | I15: Weapon 2
B16: =IF(ISNUMBER(SEARCH(IFERROR(VLOOKUP(Pilot!B15,Skills[],14,0),"#"), Zoid!C36)), IFERROR(VLOOKUP(Pilot!B15,Skills[],7,0), 0), 0) -> 0 | C16: =IF(ISNUMBER(SEARCH(IFERROR(VLOOKUP(Pilot!B19,Skills[],14,0),"#"), Zoid!C36)), IFERROR(VLOOKUP(Pilot!B19,Skills[],7,0), 0), 0) -> 0 | D16: =IF(ISNUMBER(SEARCH(IFERROR(VLOOKUP(Pilot!B23,Skills[],14,0),"#"), Zoid!C36)), IFERROR(VLOOKUP(Pilot!B23,Skills[],7,0), 0), 0) -> 0 | E16: =IF(ISNUMBER(SEARCH(IFERROR(VLOOKUP(Pilot!B27,Skills[],14,0),"#"), Zoid!C36)), IFERROR(VLOOKUP(Pilot!B27,Skills[],7,0), 0), 0) -> 0 | F16: =IF(ISNUMBER(SEARCH(IFERROR(VLOOKUP(Pilot!B31,Skills[],14,0),"#"), Zoid!C36)), IFERROR(VLOOKUP(Pilot!B31,Skills[],7,0), 0), 0) -> 0 | G16: =IF(ISNUMBER(SEARCH(IFERROR(VLOOKUP(Pilot!B35,Skills[],14,0),"#"), Zoid!C36)), IFERROR(VLOOKUP(Pilot!B35,Skills[],7,0), 0), 0) -> 0 | H16: =SUM(B16, C16, D16, E16, F16, G16) -> 0 | I16: Weapon 3
B17: =IF(ISNUMBER(SEARCH(IFERROR(VLOOKUP(Pilot!B15,Skills[],14,0),"#"), Zoid!C41)), IFERROR(VLOOKUP(Pilot!B15,Skills[],7,0), 0), 0) -> 0 | C17: =IF(ISNUMBER(SEARCH(IFERROR(VLOOKUP(Pilot!B19,Skills[],14,0),"#"), Zoid!C41)), IFERROR(VLOOKUP(Pilot!B19,Skills[],7,0), 0), 0) -> 0 | D17: =IF(ISNUMBER(SEARCH(IFERROR(VLOOKUP(Pilot!B23,Skills[],14,0),"#"), Zoid!C41)), IFERROR(VLOOKUP(Pilot!B23,Skills[],7,0), 0), 0) -> 0 | E17: =IF(ISNUMBER(SEARCH(IFERROR(VLOOKUP(Pilot!B27,Skills[],14,0),"#"), Zoid!C41)), IFERROR(VLOOKUP(Pilot!B27,Skills[],7,0), 0), 0) -> 0 | F17: =IF(ISNUMBER(SEARCH(IFERROR(VLOOKUP(Pilot!B31,Skills[],14,0),"#"), Zoid!C41)), IFERROR(VLOOKUP(Pilot!B31,Skills[],7,0), 0), 0) -> 0 | G17: =IF(ISNUMBER(SEARCH(IFERROR(VLOOKUP(Pilot!B35,Skills[],14,0),"#"), Zoid!C41)), IFERROR(VLOOKUP(Pilot!B35,Skills[],7,0), 0), 0) -> 0 | H17: =SUM(B17, C17, D17, E17, F17, G17) -> 0 | I17: Weapon 4
B18: =IF(ISNUMBER(SEARCH(IFERROR(VLOOKUP(Pilot!B15,Skills[],14,0),"#"), Zoid!C48)), IFERROR(VLOOKUP(Pilot!B15,Skills[],7,0), 0), 0) -> 0 | C18: =IF(ISNUMBER(SEARCH(IFERROR(VLOOKUP(Pilot!B19,Skills[],14,0),"#"), Zoid!C48)), IFERROR(VLOOKUP(Pilot!B19,Skills[],7,0), 0), 0) -> 0 | D18: =IF(ISNUMBER(SEARCH(IFERROR(VLOOKUP(Pilot!B23,Skills[],14,0),"#"), Zoid!C48)), IFERROR(VLOOKUP(Pilot!B23,Skills[],7,0), 0), 0) -> 0 | E18: =IF(ISNUMBER(SEARCH(IFERROR(VLOOKUP(Pilot!B27,Skills[],14,0),"#"), Zoid!C48)), IFERROR(VLOOKUP(Pilot!B27,Skills[],7,0), 0), 0) -> 0 | F18: =IF(ISNUMBER(SEARCH(IFERROR(VLOOKUP(Pilot!B31,Skills[],14,0),"#"), Zoid!C48)), IFERROR(VLOOKUP(Pilot!B31,Skills[],7,0), 0), 0) -> 0 | G18: =IF(ISNUMBER(SEARCH(IFERROR(VLOOKUP(Pilot!B35,Skills[],14,0),"#"), Zoid!C48)), IFERROR(VLOOKUP(Pilot!B35,Skills[],7,0), 0), 0) -> 0 | H18: =SUM(B18, C18, D18, E18, F18, G18) -> 0 | I18: Weapon 5
B19: =IF(ISNUMBER(SEARCH(IFERROR(VLOOKUP(Pilot!B15,Skills[],14,0),"#"), Zoid!C55)), IFERROR(VLOOKUP(Pilot!B15,Skills[],7,0), 0), 0) -> 0 | C19: =IF(ISNUMBER(SEARCH(IFERROR(VLOOKUP(Pilot!B19,Skills[],14,0),"#"), Zoid!C55)), IFERROR(VLOOKUP(Pilot!B19,Skills[],7,0), 0), 0) -> 0 | D19: =IF(ISNUMBER(SEARCH(IFERROR(VLOOKUP(Pilot!B23,Skills[],14,0),"#"), Zoid!C55)), IFERROR(VLOOKUP(Pilot!B23,Skills[],7,0), 0), 0) -> 0 | E19: =IF(ISNUMBER(SEARCH(IFERROR(VLOOKUP(Pilot!B27,Skills[],14,0),"#"), Zoid!C55)), IFERROR(VLOOKUP(Pilot!B27,Skills[],7,0), 0), 0) -> 0 | F19: =IF(ISNUMBER(SEARCH(IFERROR(VLOOKUP(Pilot!B31,Skills[],14,0),"#"), Zoid!C55)), IFERROR(VLOOKUP(Pilot!B31,Skills[],7,0), 0), 0) -> 0 | G19: =IF(ISNUMBER(SEARCH(IFERROR(VLOOKUP(Pilot!B35,Skills[],14,0),"#"), Zoid!C55)), IFERROR(VLOOKUP(Pilot!B35,Skills[],7,0), 0), 0) -> 0 | H19: =SUM(B19, C19, D19, E19, F19, G19) -> 0 | I19: Weapon 6
B20: =IF(ISNUMBER(SEARCH(IFERROR(VLOOKUP(Pilot!B15,Skills[],14,0),"#"), Zoid!C62)), IFERROR(VLOOKUP(Pilot!B15,Skills[],7,0), 0), 0) -> 0 | C20: =IF(ISNUMBER(SEARCH(IFERROR(VLOOKUP(Pilot!B19,Skills[],14,0),"#"), Zoid!C62)), IFERROR(VLOOKUP(Pilot!B19,Skills[],7,0), 0), 0) -> 0 | D20: =IF(ISNUMBER(SEARCH(IFERROR(VLOOKUP(Pilot!B23,Skills[],14,0),"#"), Zoid!C62)), IFERROR(VLOOKUP(Pilot!B23,Skills[],7,0), 0), 0) -> 0 | E20: =IF(ISNUMBER(SEARCH(IFERROR(VLOOKUP(Pilot!B27,Skills[],14,0),"#"), Zoid!C62)), IFERROR(VLOOKUP(Pilot!B27,Skills[],7,0), 0), 0) -> 0 | F20: =IF(ISNUMBER(SEARCH(IFERROR(VLOOKUP(Pilot!B31,Skills[],14,0),"#"), Zoid!C62)), IFERROR(VLOOKUP(Pilot!B31,Skills[],7,0), 0), 0) -> 0 | G20: =IF(ISNUMBER(SEARCH(IFERROR(VLOOKUP(Pilot!B35,Skills[],14,0),"#"), Zoid!C62)), IFERROR(VLOOKUP(Pilot!B35,Skills[],7,0), 0), 0) -> 0 | H20: =SUM(B20, C20, D20, E20, F20, G20) -> 0 | I20: Weapon 7
B21: =IF(ISNUMBER(SEARCH(IFERROR(VLOOKUP(Pilot!B15,Skills[],14,0),"#"), Zoid!C69)), IFERROR(VLOOKUP(Pilot!B15,Skills[],7,0), 0), 0) -> 0 | C21: =IF(ISNUMBER(SEARCH(IFERROR(VLOOKUP(Pilot!B19,Skills[],14,0),"#"), Zoid!C69)), IFERROR(VLOOKUP(Pilot!B19,Skills[],7,0), 0), 0) -> 0 | D21: =IF(ISNUMBER(SEARCH(IFERROR(VLOOKUP(Pilot!B23,Skills[],14,0),"#"), Zoid!C69)), IFERROR(VLOOKUP(Pilot!B23,Skills[],7,0), 0), 0) -> 0 | E21: =IF(ISNUMBER(SEARCH(IFERROR(VLOOKUP(Pilot!B27,Skills[],14,0),"#"), Zoid!C69)), IFERROR(VLOOKUP(Pilot!B27,Skills[],7,0), 0), 0) -> 0 | F21: =IF(ISNUMBER(SEARCH(IFERROR(VLOOKUP(Pilot!B31,Skills[],14,0),"#"), Zoid!C69)), IFERROR(VLOOKUP(Pilot!B31,Skills[],7,0), 0), 0) -> 0 | G21: =IF(ISNUMBER(SEARCH(IFERROR(VLOOKUP(Pilot!B35,Skills[],14,0),"#"), Zoid!C69)), IFERROR(VLOOKUP(Pilot!B35,Skills[],7,0), 0), 0) -> 0 | H21: =SUM(B21, C21, D21, E21, F21, G21) -> 0 | I21: Weapon 8
A23: =Zoid!G19 -> Black | B23: =IF(Zoid!G17=TRUE(),VLOOKUP(A23,A25:F28,2, FALSE()),0) -> 0 | C23: =IF(Zoid!G17=TRUE(),VLOOKUP(A23,A25:F28, 3, FALSE()),0) -> 0 | D23: =IF(Zoid!G17=TRUE(),VLOOKUP(A23,A25:F28, 4, FALSE()),0) -> 0 | E23: =IF(Zoid!G17=TRUE(), VLOOKUP(A23,A25:F28, 5, FALSE()),0) -> 0 | F23: =IF(Zoid!G17=TRUE(), VLOOKUP(A23,A25:F28, 6, FALSE()),0) -> 0 | G23: =IF(Zoid!G17=TRUE(), VLOOKUP(A23,A25:G28, 7, FALSE()),0) -> 0 | H23: =IF(Zoid!G17=TRUE(), VLOOKUP(A23,A25:F28, 6, FALSE()),0) -> 0
A24: Color | B24: Health | C24: Defense | D24: Speed | E24: Range | F24: To Hit | G24: Shield | H24: Damage increase
A25: White | B25: =VLOOKUP(Zoid!G18,Organoid!A:B,2,FALSE()) -> 0.05 | C25: =VLOOKUP(Zoid!G18,Organoid!A:C,3,FALSE()) -> 0.02 | D25: =VLOOKUP(Zoid!G18,Organoid!A:D,4,FALSE()) -> 0.01 | E25: =VLOOKUP(Zoid!G18,Organoid!A:E,5,FALSE()) -> 0.01 | F25: =VLOOKUP(Zoid!G18,Organoid!A:G,6,FALSE()) -> 0.01 | G25: =VLOOKUP(Zoid!G18,Organoid!A:V,22,FALSE()) -> 0 | H25: =VLOOKUP(Zoid!G18,Organoid!A:G,6,FALSE()) -> 0.01
A26: Red | B26: =VLOOKUP(Zoid!G18,Organoid!A:H,7,FALSE()) -> 0.01 | C26: =VLOOKUP(Zoid!G18,Organoid!A:I,8,FALSE()) -> 0.05 | D26: =VLOOKUP(Zoid!G18,Organoid!A:J,9,FALSE()) -> 0.01 | E26: =VLOOKUP(Zoid!G18,Organoid!A:K,10,FALSE()) -> 0.01 | F26: =VLOOKUP(Zoid!G18,Organoid!A:L,11,FALSE()) -> 0.02 | G26: =VLOOKUP(Zoid!C9,Organoid!A:W,23,FALSE()) -> 0 | H26: =VLOOKUP(Zoid!G18,Organoid!A:L,11,FALSE()) -> 0.02
A27: Blue | B27: =VLOOKUP(Zoid!G18,Organoid!A:M,12,FALSE()) -> 0.01 | C27: =VLOOKUP(Zoid!G18,Organoid!A:N,13,FALSE()) -> 0.01 | D27: =VLOOKUP(Zoid!G18,Organoid!A:O,14,FALSE()) -> 0.05 | E27: =VLOOKUP(Zoid!G18,Organoid!A:P,15,FALSE()) -> 0.02 | F27: =VLOOKUP(Zoid!G18,Organoid!A:Q,16,FALSE()) -> 0.01 | G27: =VLOOKUP(Zoid!C9,Organoid!A:X,24,FALSE()) -> 0 | H27: =VLOOKUP(Zoid!G18,Organoid!A:Q,16,FALSE()) -> 0.01
A28: Black | B28: =VLOOKUP(Zoid!G18,Organoid!A:R,17,FALSE()) -> 0.01 | C28: =VLOOKUP(Zoid!G18,Organoid!A:S,18,FALSE()) -> 0.01 | D28: =VLOOKUP(Zoid!G18,Organoid!A:T,19,FALSE()) -> 0.02 | E28: =VLOOKUP(Zoid!G18,Organoid!A:U,20,FALSE()) -> 0.01 | F28: =VLOOKUP(Zoid!G18,Organoid!A:U,21,FALSE()) -> 0.05 | G28: =VLOOKUP(Zoid!C9,Organoid!A:Y,25,FALSE()) -> 0 | H28: =VLOOKUP(Zoid!G18,Organoid!A:U,21,FALSE()) -> 0.05

Sheet Stats
A1: Level | B1: Health | C1: Armor | D1: React | E1: Perception | F1: To Hit
A2: 1 | B2: =+50% -> 0.5 | C2: =+10% -> 0.1 | D2: =+10% -> 0.1 | E2: =+10% -> 0.1 | F2: =+10% -> 0.1
A3: 2 | B3: 0.53 | C3: 0.13 | D3: 0.11 | E3: 0.12 | F3: 0.11
A4: 3 | B4: 0.56 | C4: 0.16 | D4: 0.12 | E4: 0.14 | F4: 0.12
A5: 4 | B5: 0.59 | C5: 0.19 | D5: 0.13 | E5: 0.16 | F5: 0.13
A6: 5 | B6: 0.62 | C6: 0.22 | D6: 0.14 | E6: 0.18 | F6: 0.14
A7: 6 | B7: 0.65 | C7: 0.25 | D7: 0.15 | E7: 0.2 | F7: 0.15
A8: 7 | B8: 0.68 | C8: 0.28 | D8: 0.16 | E8: 0.22 | F8: 0.16
A9: 8 | B9: 0.71 | C9: 0.31 | D9: 0.17 | E9: 0.24 | F9: 0.17
A10: 9 | B10: 0.74 | C10: 0.34 | D10: 0.18 | E10: 0.26 | F10: 0.18
A11: 10 | B11: 0.77 | C11: 0.37 | D11: 0.19 | E11: 0.28 | F11: 0.19
A12: 11 | B12: 0.8 | C12: 0.4 | D12: 0.2 | E12: 0.3 | F12: 0.2
A13: 12 | B13: 0.83 | C13: 0.43 | D13: 0.21 | E13: 0.32 | F13: 0.21
A14: 13 | B14: 0.86 | C14: 0.47 | D14: 0.22 | E14: 0.34 | F14: 0.22
... A101: 100 | B101: 3.45 | C101: 3.09 | D101: 1.09 | E101: 2.08 | F101: 1.09
A104: Level | B104: Health | C104: Armor | D104: React | E104: Perception | F104: To Hit
A105: 1 | B105: =+50% -> 0.5 | C105: =+10% -> 0.1 | D105: =+10% -> 0.1 | E105: =+10% -> 0.1 | F105: =+10% -> 0.1
A106: 2 | B106: 0.52 | C106: 0.11 | D106: 0.11 | E106: 0.13 | F106: 0.13
A107: 3 | B107: 0.54 | C107: 0.12 | D107: 0.12 | E107: 0.16 | F107: 0.16
A108: 4 | B108: 0.56 | C108: 0.13 | D108: 0.13 | E108: 0.19 | F108: 0.19
A109: 5 | B109: 0.58 | C109: 0.14 | D109: 0.14 | E109: 0.22 | F109: 0.22
A110: 6 | B110: 0.6 | C110: 0.15 | D110: 0.15 | E110: 0.25 | F110: 0.25
A111: 7 | B111: 0.62 | C111: 0.16 | D111: 0.16 | E111: 0.28 | F111: 0.28
A112: 8 | B112: 0.64 | C112: 0.17 | D112: 0.17 | E112: 0.31 | F112: 0.31
A113: 9 | B113: 0.66 | C113: 0.18 | D113: 0.18 | E113: 0.34 | F113: 0.34
A114: 10 | B114: 0.68 | C114: 0.19 | D114: 0.19 | E114: 0.37 | F114: 0.37
A115: 11 | B115: 0.7 | C115: 0.2 | D115: 0.2 | E115: 0.4 | F115: 0.4
A116: 12 | B116: 0.72 | C116: 0.21 | D116: 0.21 | E116: 0.43 | F116: 0.43
A117: 13 | B117: 0.74 | C117: 0.22 | D117: 0.22 | E117: 0.47 | F117: 0.47
... A204: 100 | B204: 2.48 | C204: 1.09 | D204: 1.09 | E204: 3.09 | F204: 3.09
A207: Level | B207: Health | C207: Armor | D207: React | E207: Perception | F207: To Hit
A208: 1 | B208: =+50% -> 0.5 | C208: =+10% -> 0.1 | D208: =+10% -> 0.1 | E208: =+10% -> 0.1 | F208: =+10% -> 0.1
A209: 2 | B209: 0.51 | C209: 0.13 | D209: 0.13 | E209: 0.12 | F209: 0.11
A210: 3 | B210: 0.52 | C210: 0.16 | D210: 0.16 | E210: 0.14 | F210: 0.12
A211: 4 | B211: 0.53 | C211: 0.19 | D211: 0.19 | E211: 0.16 | F211: 0.13
A212: 5 | B212: 0.54 | C212: 0.22 | D212: 0.22 | E212: 0.18 | F212: 0.14
A213: 6 | B213: 0.55 | C213: 0.25 | D213: 0.25 | E213: 0.2 | F213: 0.15
A214: 7 | B214: 0.56 | C214: 0.28 | D214: 0.28 | E214: 0.22 | F214: 0.16
A215: 8 | B215: 0.57 | C215: 0.31 | D215: 0.31 | E215: 0.24 | F215: 0.17
A216: 9 | B216: 0.58 | C216: 0.34 | D216: 0.34 | E216: 0.26 | F216: 0.18
...

Sheet Zoid List
A1: Name 1 | B1: Base Zoid 2 | C1: Type 3 | D1: Size 4 | E1: Level Required 5 | F1: Health 6 | G1: Armor 7 | H1: Defense 8 | I1: Speed 9 | J1: Reaction 10 | K1: Range 11 | L1: Carry Capacity 12 | M1: Weapon 1 13 | N1: Effect 2 14 | O1: Damage 1 15 | P1: Type 1 16 | Q1: To Hit 1 17 | R1: Active/Passive3 18 | S1: Weapon 2 19 | T1: Effect 3 20 | U1: Damage 2 21 | V1: Type 2 22 | W1: To Hit 2 23 | X1: Shield Health 24 | Y1: Speed Increase 25 | Z1: to Hit increase 26 | AA1: Reaction increase 2 27 | AB1: Range increase 28 | AC1: Active/Passive 29 | AD1: Weapon 3 30 | AE1: Effect 4 31 | AF1: Damage 3 32 | AG1: Type 3 33 | AH1: To Hit 3 34 | AI1: Shield Health 2 35 | AJ1: Speed increase 2 36 | AK1: To Hit increase 2 37 | AL1: Reaction Increase 38 | AM1: Increase Range 39 | AN1: Active/Passive 2 40 | AO1: Weapon 4 41 | AP1: Effect 5 42 | AQ1: Damage 4 43 | AR1: Type 4 44 | AS1: To Hit 4 45 | AT1: Re-Equip Slot Type 1 46 | AU1: Removable Equipment 47 | AV1: Effect 6 48 | AW1: Damage 5 49 | AX1: Damage Type 50 | AY1: To Hit 5 51 | AZ1: Weight 52 | BA1: Re-Equip Slot Type 2 53 | BB1: Removable Equipment 2 54 | BC1: Damage 6 55 | BD1: Effect 7 56 | BE1: To Hit 6 57 | BF1: Type 5 58 | BG1: Weight 2 59 | BH1: Re-Equip Slot Type 3 60 | BI1: Removable Equipment 3 61 | BJ1: Damage 7 62 | BK1: To Hit 7 63 | BL1: Weight 3 64 | BM1: Re-Equip Slot Type 4 65 | BN1: Removable Equipment 4 66 | BO1: Damage 8 67 | BP1: To Hit 8 68 | BQ1: Effect 69 | BR1: Weight 4. 70 | BS1: Defense increase for solo shield 71 | BT1: On/off 72 | BU1: Zoid Picture Base | BV1: Zoid Picture Red | BW1: Zoid Green 47 | BX1: Zoid Blue 48 | BY1: Zoid White 49 | BZ1: Zoid Black 50 | CA1: Zoid Purple 51 | CB1: Zoid Brown 52 | CC1: First attack gif | CD1: Second attack gif | CE1: Third attack gif | CF1: Fourth attack gif | CG1: Weapon 1 Heat | CH1: Weapon 2 Heat | CI1: Weapon 3 Heat | CJ1: Weapon 4 Heat | CK1: Column 83
A2: Zaber Fang Old | C2: Tiger | D2: Large | E2: 6 | F2: 200 | G2: 22 | H2: 10 | I2: 200 | J2: 15 | K2: 300 | L2: 40 | M2: 3 Shock Cannon: | N2: Chest mounted triple barreled cannon. Targets a single opponent. | O2: 80 | P2: Ranged, Explosive | Q2: 14 | S2: 20mm: | T2: Shoulder mounted laser gun. Targets a single opponent. Ranged | U2: 60 | V2: Ranged, Energy | W2: 17 | AD2: Laser Machine Gun: | AE2: Chest mounted laser gun. Targets up to two opponents. Two bursts of energy bolts that split that damage between them. | AF2: 45 | AG2: Ranged, Energy | AH2: 17 | AO2: Killer Saber: | AP2: Front claw attack. Targets a single opponent. | AQ2: 130 | AR2: Melee, Slashing | AS2: 13 | AT2: Weapon and Assist | AU2: Double Beam Cannon: | AV2: Back mounted removable cannon. Targets a single opponent. (Only usable by Zaber Fang Old) | AW2: 12D10 | AX2: Ranged, Energy | AY2: 18 | AZ2: 15 | BA2: Weapon and Assist | BH2: Weapon and Assist | BM2: Assist | CC2: https://drive.google.com/file/d/1QrN6lz-o5Xx2XJOgrZTd3B-jem0QrbCz/view?usp=share_link
A3: Zaber Fang | B3: Zaber Fang Old | C3: Tiger | D3: Large | E3: 8 | F3: 220 | G3: 23 | H3: 15 | I3: 240 | J3: 15 | K3: 300 | L3: 40 | M3: 3 Barrel Shock Cannon: | N3: Chest mounted triple barrled cannon. Targets a single opponent. | O3: 120 | P3: Ranged, Explosive | Q3: 14 | S3: 20mm: | T3: Shoulder mounted lasers. Targets a single opponent. | U3: 120 | V3: Ranged, Energy | W3: 17 | AD3: Killer Saber: | AE3: Front claw attack. Targets a single opponent. | AF3: 140 | AG3: Melee, Slashing | AH3: 13 | AQ3: 45 | AT3: Weapon and Assist | AU3: Double Beam Cannon: | AV3: Back mounted removable cannon. Targets a single opponent. (Zaber Fang Only) | AW3: 12D10 | AX3: Ranged, Energy | AY3: 18 | AZ3: 15 | BA3: Weapon and Assist | BH3: Weapon and Assist | BM3: Assist
A4: Zaber Fang RS | B4: Zaber Fang | C4: Tiger | D4: Large | E4: 13 | F4: 250 | G4: 23 | H4: 22 | I4: 240 | J4: 16 | K4: 500 | L4: 50 | M4: 3 Barrel Shock Cannon: | N4: Chest mounted triple barrel cannon. Targets a single opponent. | O4: 120 | P4: Ranged, Explosive | Q4: 16 | S4: 20mm: | T4: Shoulder mounted lasers. Targets a single opponent. | U4: 60 | V4: Ranged, Energy | W4: 17 | AD4: Killer Saber: | AE4: Front claws attack. Targets a single opponent. | AF4: 160 | AG4: Melee, Slashing | AH4: 13 | AT4: Weapon and Assist | AU4: Double Beam Cannon: | AV4: Back mounted removable cannon. Targets a single opponnent. (Zaber Fang Only) | AW4: 12D10 | AX4: Energy | AY4: 18 | AZ4: 15 | BA4: Weapon and Assist | BH4: Weapon and Assist | BM4: Assist
A5: Zaber Fang SS | B5: Zaber Fang | C5: Tiger | D5: Large | E5: 11 | F5: 220 | G5: 23 | H5: 20 | I5: 240 | J5: 16 | K5: 500 | L5: 40 | M5: 3 Barrel Shock Cannon: | N5: Chest mounted triple barrel cannon. Targets a single opponent. | O5: 120 | P5: Ranged, Explosive | Q5: 14 | S5: Beam Gun: | T5: Back mounted energy gun. Targets a single opponent. | U5: 60 | V5: Ranged, Energy | W5: 17 | AD5: Beam Gatling: | AE5: Target up to two opponents. Shoots two bursts of energy that split the damage. | AF5: 90 | AG5: Ranged, Energy, Close Range | AH5: 16 | AO5: Killer Saber: | AP5: Claw attack. Targets a single opponent. | AQ5: 160 | AR5: Melee, Slashing | AS5: 13 | AT5: Weapon and Assist | BA5: Weapon and Assist | BH5: Weapon and Assist | BM5: Assist
A6: Zaber Fang AT | B6: Zaber Fang | C6: Tiger | D6: Large | E6: 10 | F6: 230 | G6: 23 | H6: 17 | I6: 250 | J6: 15 | K6: 400 | L6: 40 | M6: 3 Barrel Shock Cannon: | N6: Chest mounted triple barrel cannon. Targets a single opponent. | O6: 120 | P6: Ranged, Explosive | Q6: 14 | S6: 8-Missile Pod: | T6: Back mounted missile pod. Targets up to four opponents. Shoots four missiles with the damage split between them. | U6: 75 | V6: Ranged, Explosive, Homing | W6: 18 | AD6: Killer Saber: | AE6: Bite attack. targets a single opponent | AF6: 160 | AG6: Melee, Piercing | AH6: 13 | AT6: Assist | BA6: Weapon and Assist | BH6: Weapon and Assist | BM6: Assist
A7: Zaber Fang TS | B7: Zaber Fang AT | C7: Tiger | D7: Large | E7: 8 | F7: 230 | G7: 23 | H7: 20 | I7: 250 | J7: 15 | K7: 300 | L7: 40 | M7: 3 Barrel Shock Cannon: | N7: Chest mounted triple barrel cannon. Targets a single opponent. | O7: 140 | P7: Ranged, Explosive | Q7: 14 | S7: Short Range Cannon: | T7: Back mounted cannon. Targets a single opponent. | U7: 160 | V7: Ranged, Explosive | W7: 13 | AD7: Killer Saber: | AE7: Bite attack. Targets a single opponent. | AF7: 160 | AG7: Melee, Piercing | AH7: 13 | AT7: Assist | BA7: Weapon and Assist | BH7: Weapon and Assist | BM7: Assist
A8: Proto Zaber | B8: Zaber Fang | C8: Tiger | D8: Large | E8: 18 | F8: 260 | G8: 22 | H8: 25 | I8: 250 | J8: 14 | K8: 300 | L8: 30 | M8: Triple Impact Cannon: | N8: Chest mounted cannon. Targets a single opponent. | O8: 170 | P8: Ranged, Explosive | Q8: 17 | S8: Linear Laser Gun: | T8: Shoulder mounted laser beam gun. Targets a single opponent. | U8: 100 | V8: Ranged, Energy | W8: 17 | AD8: SR Vulcan: | AE8: Shoulder mounted machine gun. Targets up to two Zoids. Two bursts that deals 5D8 piercing. | AF8: 80 | AG8: Ranged, Piercing | AH8: 17 | AO8: Killer Saber: | AP8: Bite attack. Targets a single opponent. | AQ8: 180 | AR8: Melee, Piercing | AS8: 17 | AT8: Weapon and Assist | AU8: Double Beam Cannon: back mounted energy cannon. Targets a single opponent. Ranged (Proto Fang Only) | AW8: 20D10 | AX8: Energy | AY8: 18 | AZ8: 17 | BA8: Weapon and Assist | BH8: Weapon and Assist | BM8: Assist
A9: Diablo Tiger | C9: Tiger | D9: Medium | E9: 25 | F9: 350 | G9: 23 | H9: 75 | I9: 240 | J9: 18 | K9: 300 | L9: 20 | M9: Cyber Cannon: | N9: Back mounted cannon. Targets a vertical area 30m wide by 60m long. Opponents in the area of effect must make a reaction save against the attack roll. Successful saves take no damage. | O9: 180 | P9: Ranged, Energy | Q9: 18 | S9: Cyber Claw: | T9: Claw attack. Targets a single opponent. | U9: 350 | V9: Melee, Slashing | W9: 15 | AD9: Optical Camouflage: | AE9: Stealth generator. Self targeting stealth field. Turn "invisible". Lasts for 5 turns. Disadvatage on attack rolls against you. Advantage on stealth cheacks. | AF9: 0 | AN9: Active | AO9: Cyber Fang: | AP9: Bite attack. Targets a single opponent. | AQ9: 400 | AR9: Melee, Piercing | AS9: 13 | AT9: Assist | BA9: Weapon and Assist | BH9: Weapon and Assist | BM9: Assist | BN9: Auto Repair Unit: self repair function. | BQ9: 50 healing. must recharg for two turns before next use | BR9: 15 | BT9: Active
A10: Blitz Tiger | C10: Tiger | D10: Large | F10: 400 | G10: 23 | H10: 75 | I10: 320 | J10: 14 | K10: 500 | L10: 30 | M10: Thunder Claw: | N10: Claw electric attack. Targets a single opponent. On a hit must make a percentile roll. If the roll is 49 or lower their zoid is frozen. At the end of their turn they may roll again to unfreeze. | O10: 180 | P10: Melee, Freeze, Slashing | Q10: 15 | S10: Lightning Attack: | T10: Head and shoulder mounted blades shift forward. Targets a single opponent. On a hit must make a percentile roll. If the roll is 49 or lower their zoid is frozen. At the end of their turn they may roll again to unfreeze. | U10: 360 | V10: Melee, Slashing, Freeze, Lighting | W10: 16 | AD10: Volt Cannon: | AE10: Back mounted electric cannon. Targets an area of 45m by 135m. Must make a reaction save against the attack roll. On a successful save you take no damage. On a hit must make a percentile roll. If the roll is 49 or lower their zoid is frozen. At the end of their turn they may roll again to unfreeze. | AF10: 120 | AG10: Ranged, Freeze, Lighting | AH10: 12 | AO10: Crusher Saber: | AP10: Bite attack. Targets a single opponent. | AQ10: 250 | AR10: Melee, Piercing | AS10: 14 | AT10: Assist | BA10: Weapon and Assist | BH10: Weapon and Assist | BM10: Assist
A11: Atak Kat | C11: Tiger | D11: Small | E11: 7 | F11: 100 | G11: 20 | H11: 9 | I11: 190 | J11: 16 | K11: 1800 | L11: 20 | M11: Laser Machine Gun: | N11: Chest mounted energy gun. Can target up to two Zoids. Shoots two energy bolts dealing 3D6 energy | O11: 30 | P11: Ranged, Energy | Q11: 17 | S11: Optical Camouflage: | T11: Self targeting stealth field. Turn “invisible”. Lasts for 5 turns. Disadvantage on attack rolls against you. Advantage on stealth checks. | AC11: Active | AD11: Go for Broke: | AE11: Claw attack. Targets a single opponent. | AF11: 60 | AG11: Melee, Slashing | AH11: 13 | AT11: Weapon and Assist | AU11: Double Beam Cannon: | AV11: back mounted energy weapon. Targets a single opponent. Ranged (Atak Kat Only) | AW11: 60 | AX11: Energy | AY11: 17 | AZ11: 8 | BA11: Weapon and Assist | BH11: Weapon and Assist | BM11: Assist
A12: Lightning Saix | C12: Tiger | D12: Medium | E12: 12 | F12: 230 | G12: 22 | H12: 17 | I12: 325 | J12: 18 | K12: 200 | L12: 30 | M12: 2-Barrel Vulcan Cannon: | N12: Head mounted machine gun. Covers an area of 60m by 60m. Targets in the area must make a reaction against the attack roll. Successful saves take no damage. | O12: 55 | P12: Ranged, Piercing | Q12: 17 | S12: Killer Fang: | T12: Bite attack. Targets a single opponent. | U12: 130 | V12: Melee, Piercing | W12: 13 | AF12: 0 | AT12: Weapon and Assist | AU12: Pulse Laser Gun: | AV12: back mounted energy gun. Targets up to two opponents. Ranged (Lightning Saix Only) | AW12: 110 | AX12: Energy | AY12: 18 | AZ12: 20 | BA12: Weapon and Assist | BH12: Weapon and Assist | BM12: Assist
A13: Lightning Saix BS | B13: Lightning Saix | C13: Tiger | D13: Medium | E13: 13 | F13: 230 | G13: 22 | H13: 17 | I13: 310 | J13: 17 | K13: 200 | L13: 25 | M13: 2-Barrel Vulcan Cannon: | N13: Head mounted machine gun. Covers an area of 60m by 60m. | O13: 55 | P13: Ranged, Piercing | Q13: 17 | S13: Killer Fang: | T13: Bite attack. Targets a single opponent. | U13: 130 | V13: Melee, Piercing | W13: 13 | AF13: 0 | AT13: Weapon and Assist | AU13: Pulse Laser Gun: | AV13: back mounted energy gun. Targets up to two opponents. Ranged (Lightning Saix Only) | AW13: 130 | AX13: Energy | AY13: 19 | AZ13: 22 | BA13: Weapon and Assist | BH13: Weapon and Assist | BM13: Assist
A14: Gun Tiger | C14: Tiger | D14: Small | E14: 3 | F14: 85 | G14: 18 | H14: 8 | I14: 270 | J14: 18 | K14: 500 | L14: 20 | M14: High Wave Frequency Claw: | N14: Claw attack. Targets a single opponent. | O14: 35 | P14: Melee, Slashing | Q14: 17 | S14: Static Minigun: | T14: Shoulder mounted minigun. Targets a single opponent. | U14: 65 | V14: Ranged, Piercing | W14: 16 | AD14: Ion Booster: | AE14: Back mounted boosters. 300 speed for three turns | AJ14: 300 | AN14: Active | AO14: High Wave Frequency Fang: | AP14: Bite attack. Targets a single opponent. | AQ14: 40 | AR14: Melee, Piercing | AS14: 14 | AT14: Assist | BA14: Weapon and Assist | BH14: Weapon and Assist | BM14: Assist
A15: Liger Zero | C15: Lion | D15: Large | E15: 15 | F15: 260 | G15: 23 | H15: 28 | I15: 307 | J15: 15 | K15: 350 | L15: 40 | M15: Shock Cannon: | N15: Chest mounted cannon. Targets a single opponent. | O15: 160 | P15: Ranged, Explosive | Q15: 15 | S15: Ion Boosters: | T15: Back mounted boosters. Doubles speed for three turns | Y15: =Zoid!D17 -> #NAME? | AC15: Active | AD15: Strike Laster Claw: | AE15: Energy claw attack. Targets a single opponent. | AF15: 240 | AG15: Melee, Slashing, Energy | AH15: 15 | AT15: Assist | BA15: Weapon and Assist | BH15: Weapon and Assist | BM15: Assist
A16: Zero Schneider (CAU) | B16: Liger Zero | C16: Lion | D16: Large | E16: 17 | F16: 290 | G16: 24 | H16: 28 | I16: 310 | J16: 16 | K16: 200 | L16: 30 | M16: Shock Cannon: | N16: Chest mounted cannon. Targets a single opponent. | O16: 160 | P16: Ranged, Explosive | Q16: 15 | S16: 5-Blades: | T16: Five blades flip forward from the back. Targets a single opponent. | U16: 400 | V16: Melee, Slashing | W16: 10 | AD16: Energy Shield: | AE16: Curved domed energy shield. Blocks 200 damage before dispersing. Must recharge for two turns | AI16: 200 | AN16: Active | AO16: Laser Blade: | AP16: Two blades flip down and out from the sides. Targets a single opponent. | AQ16: 270 | AR16: Melee, Slashing | AS16: 14 | AT16: Assist | BA16: Weapon and Assist | BH16: Weapon and Assist | BM16: Assist | CH16: 1
A17: Zero Jager (CAU) | B17: Liger Zero | C17: Lion | D17: Large | E17: 17 | F17: 260 | G17: 24 | H17: 28 | I17: 330 | J17: 18 | K17: 400 | L17: 30 | M17: Shock Cannon: | N17: Chest mounted cannon. Targets a single opponent. | O17: 160 | P17: Ranged, Explosive | Q17: 15 | S17: Vulcan Pod: | T17: Head mounted guns. Targets a single opponent. | U17: 95 | V17: Ranged, Piercing | W17: 17 | AD17: Ion Boosters: | AE17: Back mounted boosters. Increases speed by 500 for three turns. | AJ17: 500 | AN17: Active | AO17: Strike Laser Claws: | AP17: Energy claw attack. Targets a single opponent. | AQ17: 240 | AR17: Melee, Slashing, Energy | AS17: 15 | AT17: Assist | BA17: Weapon and Assist | BH17: Weapon and Assist | BM17: Assist
A18: Zero Panzer (CAU) | B18: Liger Zero | C18: Lion | D18: Large | E18: 20 | F18: 300 | G18: 26 | H18: 40 | I18: 285 | J18: 15 | K18: 200 | L18: 30 | M18: Grenade Launcher: | N18: Chest mounted grenade launcher. Targets a single opponent. | O18: 200 | P18: Ranged, Explosive | Q18: 18 | S18: Hybrid Cannons: | T18: Back mounted cannons. Targets an area of 90m square. Targets in the area must make a reaction save against the attack roll. Successful saves take no damage. | U18: 250 | V18: Ranged, Piercing, Long Range | W18: 18 | AD18: Burning Big Bang: | AE18: All out barrage using all guns. Can only be used twice per battle. Targets an area 120m square. Targets in the area of effect must make a reaction save against your attack roll. Successful saves take no damage. | AF18: 300 | AG18: Ranged, Homing, Explosive | AH18: 16 | AO18: Strike Laser Claw: | AP18: Energy claw attack. Targets a single opponent. | AQ18: 240 | AR18: Melee, Slashing, Energy | AS18: 12 | AT18: Assist | BA18: Weapon and Assist | BH18: Weapon and Assist | BM18: Assist | CH18: 2 | CI18: 1
A19: Zero Empire (CAU) | B19: Liger Zero | C19: Lion | D19: Large | E19: 15 | F19: 260 | G19: 22 | H19: 28 | I19: 307 | J19: 15 | K19: 400 | L19: 40 | M19: Shock Cannon: | N19: Chest mounted cannon. Targets a single opponent. | O19: 160 | P19: Ranged, Explosive | Q19: 15 | S19: Ion Booster: | T19: Back mounted boosters that increases your Zoids speed by 400 for three turns. | Y19: 400 | AC19: Active | AD19: Strike Laser Claw: | AE19: Energy claw attack. Targets a single opponent. | AF19: 210 | AG19: Melee, Slashing, Energy | AH19: 15 | AT19: Assist | BA19: Weapon and Assist | BH19: Weapon and Assist | BM19: Assist
